<?xml version="1.0" encoding="UTF-8"?>
<sdf version='1.9'>
  <model name='PLACE_mockup'>
    <pose>0 0 .24 0 0 0</pose>
    <self_collide>false</self_collide>
    <static>false</static>
    <link name="base_link">
      <inertial>
        <mass>5.0</mass>
        <inertia>
          <ixx>0.197166667</ixx>
          <ixy>0</ixy>
          <ixz>0</ixz>
          <iyy>0.197166667</iyy>
          <iyz>0</iyz>
          <izz>0.34225</izz>
          <!--<ixx>3.20066667</ixx>
          <ixy>0</ixy>
          <ixz>0</ixz>
          <iyy>3.20066667</iyy>
          <iyz>0</iyz>
          <izz>6.4</izz>-->
          <!--<ixx>0.02166666666666667</ixx>
          <ixy>0</ixy>
          <ixz>0</ixz>
          <iyy>0.02166666666666667</iyy>
          <iyz>0</iyz>
          <izz>0.04000000000000001</izz>-->
        </inertia>
      </inertial>
      <gravity>true</gravity>
      <velocity_decay/>
      <visual name="base_link_visual">
        <pose>0 0 0.15 0 0 1.57</pose>
        <geometry>
          <mesh>
            <scale>1 1 1</scale>
            <uri>model://PLACE_mockup/meshes/PLACE_mockup_coloured_2.dae</uri>
          </mesh>
        </geometry>
      </visual>
      <visual name="5010_motor_base_0">
        <pose>0 0.8 0.3315 0 0 0</pose>
        <geometry>
          <mesh>
            <scale>1 1 1</scale>
            <uri>model://PLACE_mockup/meshes/5010Base.dae</uri>
          </mesh>
        </geometry>
      </visual>
      <visual name="5010_motor_base_1">
        <pose>0.692 0.4 0.3315 0 0 0</pose>
        <geometry>
          <mesh>
            <scale>1 1 1</scale>
            <uri>model://PLACE_mockup/meshes/5010Base.dae</uri>
          </mesh>
        </geometry>
      </visual>
      <visual name="5010_motor_base_2">
        <pose>0.692 -0.4 0.3315 0 0 0</pose>
        <geometry>
          <mesh>
            <scale>1 1 1</scale>
            <uri>model://PLACE_mockup/meshes/5010Base.dae</uri>
          </mesh>
        </geometry>
      </visual>
      <visual name="5010_motor_base_3">
        <pose>0 -0.8 0.3315 0 0 0</pose>
        <geometry>
          <mesh>
            <scale>1 1 1</scale>
            <uri>model://PLACE_mockup/meshes/5010Base.dae</uri>
          </mesh>
        </geometry>
      </visual>
      <visual name="5010_motor_base_4">
        <pose>-0.692 -0.4 0.3315 0 0 0</pose>
        <geometry>
          <mesh>
            <scale>1 1 1</scale>
            <uri>model://PLACE_mockup/meshes/5010Base.dae</uri>
          </mesh>
        </geometry>
      </visual>
      <visual name="5010_motor_base_5">
        <pose>-0.692 0.4 0.3315 0 0 0</pose>
        <geometry>
          <mesh>
            <scale>1 1 1</scale>
            <uri>model://PLACE_mockup/meshes/5010Base.dae</uri>
          </mesh>
        </geometry>
      </visual>
      <visual name="NXP_FMUK66_FRONT">
        <pose>0.047 .001 .043 1 0 1.57</pose>
        <cast_shadows>false</cast_shadows>
        <geometry>
          <plane>
            <normal>0 0 1</normal>
            <size>.013 .007</size>
          </plane>
        </geometry>
        <material>
          <diffuse>1.0 1.0 1.0</diffuse>
          <specular>1.0 1.0 1.0</specular>
          <pbr>
            <metal>
              <albedo_map>model://PLACE_mockup/materials/textures/nxp.png</albedo_map>
            </metal>
          </pbr>
        </material>
      </visual>
      <visual name="NXP_FMUK66_TOP">
        <pose>-0.023 0 .0515 0 0 -1.57</pose>
        <cast_shadows>false</cast_shadows>
        <geometry>
          <plane>
            <normal>0 0 1</normal>
            <size>.013 .007</size>
          </plane>
        </geometry>
        <material>
          <diffuse>1.0 1.0 1.0</diffuse>
          <specular>1.0 1.0 1.0</specular>
          <pbr>
            <metal>
              <albedo_map>model://PLACE_mockup/materials/textures/nxp.png</albedo_map>
            </metal>
          </pbr>
        </material>
      </visual>
      <visual name="RDDRONE_FMUK66_TOP">
        <pose>-.03 0 .0515 0 0 -1.57</pose>
        <cast_shadows>false</cast_shadows>
        <geometry>
          <plane>
            <normal>0 0 1</normal>
            <size>.032 .0034</size>
          </plane>
        </geometry>
        <material>
          <diffuse>1.0 1.0 1.0</diffuse>
          <specular>1.0 1.0 1.0</specular>
          <pbr>
            <metal>
              <albedo_map>model://PLACE_mockup/materials/textures/rd.png</albedo_map>
            </metal>
          </pbr>
        </material>
      </visual>
      <collision name="base_link_collision_0">
        <pose>0 0 0.08 0 0 0</pose>
        <geometry>
          <cylinder>
            <radius>0.86</radius>
            <length>0.61</length>
          </cylinder>
        </geometry>
        <surface>
          <contact>
            <ode>
              <min_depth>0.001</min_depth>
              <max_vel>0</max_vel>
            </ode>
          </contact>
          <friction>
            <ode/>
          </friction>
        </surface>
      </collision>
      <sensor name="air_pressure_sensor" type="air_pressure">
        <always_on>1</always_on>
        <update_rate>50</update_rate>
        <air_pressure>
          <pressure>
            <noise type="gaussian">
              <mean>0</mean>
              <stddev>0.01</stddev>
            </noise>
          </pressure>
        </air_pressure>
      </sensor>
      <sensor name="imu_sensor" type="imu">
        <always_on>1</always_on>
        <update_rate>250</update_rate>
      </sensor>
    </link>
    <link name="buoyant_0">
    <gravity>true</gravity>
      <self_collide>false</self_collide>
      <velocity_decay/>
      <pose>0 0.8 0 0 0 0</pose>
      <inertial>
          <mass>2.5</mass>
          <inertia>
            <ixx>0.0293177083</ixx>
            <iyy>0.0293177083</iyy>
            <izz>0.003125</izz>
          </inertia>
      </inertial>
    </link>
    <joint name="buoyant_0_joint" type="fixed">
      <parent>base_link</parent>
      <child>buoyant_0</child>
    </joint>
    <link name="rotor_0">
      <gravity>true</gravity>
      <self_collide>false</self_collide>
      <velocity_decay/>
      <pose>0 0.8 0.3315 0 0 0</pose>
        <inertial>
          <mass>0.016076923076923075</mass>
          <!--<mass>2.5</mass>-->
          <inertia>
            <!--<ixx>0.0293177083</ixx>
            <iyy>0.0293177083</iyy>
            <izz>0.003125</izz>-->
            <ixx>3.8464910483993325e-07</ixx>
            <iyy>2.6115851691700804e-05</iyy>
            <izz>2.649858234714004e-05</izz>
          </inertia>
        </inertial>
      <visual name="rotor_0_visual">
        <pose>0 0 0.01 0 0 0</pose>
        <geometry>
          <mesh>
            <scale>1 1 1</scale>
            <uri>model://PLACE_mockup/meshes/propeller.dae</uri>
          </mesh>
        </geometry>
      </visual>
      <collision name="rotor_0_collision">
        <pose>0 0 0.01 0 0 0 </pose>
        <geometry>
          <cylinder>
            <radius>0.38</radius>
            <length>0.02</length>
          </cylinder>
        </geometry>
        <surface>
          <contact>
            <ode>
              <min_depth>0.001</min_depth>
              <max_vel>0</max_vel>
            </ode>
          </contact>
          <friction>
            <ode/>
          </friction>
        </surface>
      </collision>
    </link>
    <joint name="rotor_0_joint" type="revolute">
      <parent>base_link</parent>
      <child>rotor_0</child>
      <axis>
        <xyz>0 0 1</xyz>
        <limit>
          <lower>-1e+16</lower>
          <upper>1e+16</upper>
        </limit>
        <dynamics>
          <spring_reference>0</spring_reference>
          <spring_stiffness>0</spring_stiffness>
        </dynamics>
      </axis>
    </joint>
    <link name="buoyant_1">
    <gravity>true</gravity>
      <self_collide>false</self_collide>
      <velocity_decay/>
      <pose>0.692 0.4 0 0 0 0</pose>
      <inertial>
          <mass>2.5</mass>
          <inertia>
            <ixx>0.0293177083</ixx>
            <iyy>0.0293177083</iyy>
            <izz>0.003125</izz>
          </inertia>
      </inertial>
    </link>
    <joint name="buoyant_1_joint" type="fixed">
      <parent>base_link</parent>
      <child>buoyant_1</child>
    </joint>
    <link name="rotor_1">
      <gravity>true</gravity>
      <self_collide>false</self_collide>
      <velocity_decay/>
      <pose>0.692 0.4 0.3315 0 0 0</pose>
      <inertial>
          <mass>0.016076923076923075</mass>
          <inertia>
            <ixx>0.0293177083</ixx>
            <iyy>0.0293177083</iyy>
            <izz>0.003125</izz>
          </inertia>
        </inertial>
      <visual name="rotor_1_visual">
        <pose>0 0 0.01 0 0 0</pose>
        <geometry>
          <mesh>
            <scale>1 1 1</scale>
            <uri>model://PLACE_mockup/meshes/propeller.dae</uri>
          </mesh>
        </geometry>
      </visual>
      <collision name="rotor_1_collision">
        <pose>0 0 0.01 0 0 0 </pose>
        <geometry>
          <cylinder>
            <radius>0.38</radius>
            <length>0.02</length>
          </cylinder>
        </geometry>
        <surface>
          <contact>
            <ode>
              <min_depth>0.001</min_depth>
              <max_vel>0</max_vel>
            </ode>
          </contact>
          <friction>
            <ode/>
          </friction>
        </surface>
      </collision>
    </link>
    <joint name="rotor_1_joint" type="revolute">
      <parent>base_link</parent>
      <child>rotor_1</child>
      <axis>
        <xyz>0 0 1</xyz>
        <limit>
          <lower>-1e+16</lower>
          <upper>1e+16</upper>
        </limit>
        <dynamics>
          <spring_reference>0</spring_reference>
          <spring_stiffness>0</spring_stiffness>
        </dynamics>
      </axis>
    </joint>
    <link name="buoyant_2">
    <gravity>true</gravity>
      <self_collide>false</self_collide>
      <velocity_decay/>
      <pose>0.692 -0.4 0 0 0 0</pose>
      <inertial>
          <mass>2.5</mass>
          <inertia>
            <ixx>0.0293177083</ixx>
            <iyy>0.0293177083</iyy>
            <izz>0.003125</izz>
          </inertia>
      </inertial>
    </link>
    <joint name="buoyant_2_joint" type="fixed">
      <parent>base_link</parent>
      <child>buoyant_2</child>
    </joint>
    <link name="rotor_2">
      <gravity>true</gravity>
      <self_collide>false</self_collide>
      <velocity_decay/>
      <pose>0.692 -0.4 0.3315 0 0 0</pose>
      <inertial>
          <mass>0.016076923076923075</mass>
          <inertia>
            <ixx>3.8464910483993325e-07</ixx>
            <iyy>2.6115851691700804e-05</iyy>
            <izz>2.649858234714004e-05</izz>
          </inertia>
        </inertial>
      <visual name="rotor_2_visual">
        <pose>0 0 0.01 0 0 0</pose>
        <geometry>
          <mesh>
            <scale>1 1 1</scale>
            <uri>model://PLACE_mockup/meshes/propeller.dae</uri>
          </mesh>
        </geometry>
      </visual>
      <collision name="rotor_2_collision">
        <pose>0 0 0.01 0 0 0 </pose>
        <geometry>
          <cylinder>
            <radius>0.38</radius>
            <length>0.02</length>
          </cylinder>
        </geometry>
        <surface>
          <contact>
            <ode>
              <min_depth>0.001</min_depth>
              <max_vel>0</max_vel>
            </ode>
          </contact>
          <friction>
            <ode/>
          </friction>
        </surface>
      </collision>
    </link>
    <joint name="rotor_2_joint" type="revolute">
      <parent>base_link</parent>
      <child>rotor_2</child>
      <axis>
        <xyz>0 0 1</xyz>
        <limit>
          <lower>-1e+16</lower>
          <upper>1e+16</upper>
        </limit>
        <dynamics>
          <spring_reference>0</spring_reference>
          <spring_stiffness>0</spring_stiffness>
        </dynamics>
      </axis>
    </joint>
    <link name="buoyant_3">
    <gravity>true</gravity>
      <self_collide>false</self_collide>
      <velocity_decay/>
      <pose>0 -0.8 0 0 0 0</pose>
      <inertial>
          <mass>2.5</mass>
          <inertia>
            <ixx>0.0293177083</ixx>
            <iyy>0.0293177083</iyy>
            <izz>0.003125</izz>
          </inertia>
      </inertial>
    </link>
    <joint name="buoyant_3_joint" type="fixed">
      <parent>base_link</parent>
      <child>buoyant_3</child>
    </joint>
    <link name="rotor_3">
      <gravity>true</gravity>
      <self_collide>false</self_collide>
      <velocity_decay/>
      <pose>0 -0.8 0.3315 0 0 0</pose>
      <inertial>
          <mass>0.016076923076923075</mass>
          <inertia>
            <ixx>3.8464910483993325e-07</ixx>
            <iyy>2.6115851691700804e-05</iyy>
            <izz>2.649858234714004e-05</izz>
          </inertia>
        </inertial>
      <visual name="rotor_3_visual">
        <pose>0 0 0.01 0 0 0</pose>
        <geometry>
          <mesh>
            <scale>1 1 1</scale>
            <uri>model://PLACE_mockup/meshes/propeller.dae</uri>
          </mesh>
        </geometry>
      </visual>
      <collision name="rotor_3_collision">
        <pose>0 0 0.01 0 0 0 </pose>
        <geometry>
          <cylinder>
            <radius>0.38</radius>
            <length>0.02</length>
          </cylinder>
        </geometry>
        <surface>
          <contact>
            <ode>
              <min_depth>0.001</min_depth>
              <max_vel>0</max_vel>
            </ode>
          </contact>
          <friction>
            <ode/>
          </friction>
        </surface>
      </collision>
    </link>
    <joint name="rotor_3_joint" type="revolute">
      <parent>base_link</parent>
      <child>rotor_3</child>
      <axis>
        <xyz>0 0 1</xyz>
        <limit>
          <lower>-1e+16</lower>
          <upper>1e+16</upper>
        </limit>
        <dynamics>
          <spring_reference>0</spring_reference>
          <spring_stiffness>0</spring_stiffness>
        </dynamics>
      </axis>
    </joint>
    <link name="buoyant_4">
    <gravity>true</gravity>
      <self_collide>false</self_collide>
      <velocity_decay/>
      <pose>-0.692 -0.4 0 0 0 0</pose>
      <inertial>
          <mass>2.5</mass>
          <inertia>
            <ixx>0.0293177083</ixx>
            <iyy>0.0293177083</iyy>
            <izz>0.003125</izz>
          </inertia>
      </inertial>
    </link>
    <joint name="buoyant_4_joint" type="fixed">
      <parent>base_link</parent>
      <child>buoyant_4</child>
    </joint>
    <link name="rotor_4">
      <gravity>true</gravity>
      <self_collide>false</self_collide>
      <velocity_decay/>
      <pose>-0.692 -0.4 0.3315 0 0 0</pose>
      <inertial>
          <mass>0.016076923076923075</mass>
          <inertia>
            <ixx>3.8464910483993325e-07</ixx>
            <iyy>2.6115851691700804e-05</iyy>
            <izz>2.649858234714004e-05</izz>
          </inertia>
        </inertial>
      <visual name="rotor_4_visual">
        <pose>0 0 0.01 0 0 0</pose>
        <geometry>
          <mesh>
            <scale>1 1 1</scale>
            <uri>model://PLACE_mockup/meshes/propeller.dae</uri>
          </mesh>
        </geometry>
      </visual>
      <collision name="rotor_4_collision">
        <pose>0 0 0.01 0 0 0 </pose>
        <geometry>
          <cylinder>
            <radius>0.38</radius>
            <length>0.02</length>
          </cylinder>
        </geometry>
        <surface>
          <contact>
            <ode>
              <min_depth>0.001</min_depth>
              <max_vel>0</max_vel>
            </ode>
          </contact>
          <friction>
            <ode/>
          </friction>
        </surface>
      </collision>
    </link>
    <joint name="rotor_4_joint" type="revolute">
      <parent>base_link</parent>
      <child>rotor_4</child>
      <axis>
        <xyz>0 0 1</xyz>
        <limit>
          <lower>-1e+16</lower>
          <upper>1e+16</upper>
        </limit>
        <dynamics>
          <spring_reference>0</spring_reference>
          <spring_stiffness>0</spring_stiffness>
        </dynamics>
      </axis>
    </joint>
    <link name="buoyant_5">
    <gravity>true</gravity>
      <self_collide>false</self_collide>
      <velocity_decay/>
      <pose>-0.692 0.4 0 0 0 0</pose>
      <inertial>
          <mass>2.5</mass>
          <inertia>
            <ixx>0.0293177083</ixx>
            <iyy>0.0293177083</iyy>
            <izz>0.003125</izz>
          </inertia>
      </inertial>
    </link>
    <joint name="buoyant_5_joint" type="fixed">
      <parent>base_link</parent>
      <child>buoyant_5</child>
    </joint>
    <link name="rotor_5">
      <gravity>true</gravity>
      <self_collide>false</self_collide>
      <velocity_decay/>
      <pose>-0.692 0.4 0.3315 0 0 0</pose>
      <inertial>
          <mass>0.016076923076923075</mass>
          <inertia>
            <ixx>3.8464910483993325e-07</ixx>
            <iyy>2.6115851691700804e-05</iyy>
            <izz>2.649858234714004e-05</izz>
          </inertia>
        </inertial>
      <visual name="rotor_5_visual">
        <pose>0 0 0.01 0 0 0</pose>
        <geometry>
          <mesh>
            <scale>1 1 1</scale>
            <uri>model://PLACE_mockup/meshes/propeller.dae</uri>
          </mesh>
        </geometry>
      </visual>
      <collision name="rotor_5_collision">
        <pose>0 0 0.01 0 0 0 </pose>
        <geometry>
          <cylinder>
            <radius>0.38</radius>
            <length>0.02</length>
          </cylinder>
        </geometry>
        <surface>
          <contact>
            <ode>
              <min_depth>0.001</min_depth>
              <max_vel>0</max_vel>
            </ode>
          </contact>
          <friction>
            <ode/>
          </friction>
        </surface>
      </collision>
    </link>
    <joint name="rotor_5_joint" type="revolute">
      <parent>base_link</parent>
      <child>rotor_5</child>
      <axis>
        <xyz>0 0 1</xyz>
        <limit>
          <lower>-1e+16</lower>
          <upper>1e+16</upper>
        </limit>
        <dynamics>
          <spring_reference>0</spring_reference>
          <spring_stiffness>0</spring_stiffness>
        </dynamics>
      </axis>
    </joint>
   <plugin filename="gz-sim-multicopter-motor-model-system" name="gz::sim::systems::MulticopterMotorModel">
      <jointName>rotor_0_joint</jointName>
      <linkName>rotor_0</linkName>
      <turningDirection>cw</turningDirection>
      <timeConstantUp>0.0125</timeConstantUp>
      <timeConstantDown>0.025</timeConstantDown>
      <maxRotVelocity>3500.0</maxRotVelocity>
      <motorConstant>8.54858e-06</motorConstant>
      <momentConstant>0.650</momentConstant>
      <commandSubTopic>command/motor_speed</commandSubTopic>
      <motorNumber>0</motorNumber>
      <rotorDragCoefficient>8.06428e-05</rotorDragCoefficient>
      <rollingMomentCoefficient>1e-06</rollingMomentCoefficient>
      <rotorVelocitySlowdownSim>10</rotorVelocitySlowdownSim>
      <motorType>velocity</motorType>
    </plugin>
    <plugin filename="gz-sim-multicopter-motor-model-system" name="gz::sim::systems::MulticopterMotorModel">
      <jointName>rotor_1_joint</jointName>
      <linkName>rotor_1</linkName>
      <turningDirection>ccw</turningDirection>
      <timeConstantUp>0.0125</timeConstantUp>
      <timeConstantDown>0.025</timeConstantDown>
      <maxRotVelocity>3500.0</maxRotVelocity>
      <motorConstant>8.54858e-06</motorConstant>
      <momentConstant>0.650</momentConstant>
      <commandSubTopic>command/motor_speed</commandSubTopic>
      <motorNumber>1</motorNumber>
      <rotorDragCoefficient>8.06428e-05</rotorDragCoefficient>
      <rollingMomentCoefficient>1e-06</rollingMomentCoefficient>
      <rotorVelocitySlowdownSim>10</rotorVelocitySlowdownSim>
      <motorType>velocity</motorType>
    </plugin>
    <plugin filename="gz-sim-multicopter-motor-model-system" name="gz::sim::systems::MulticopterMotorModel">
      <jointName>rotor_2_joint</jointName>
      <linkName>rotor_2</linkName>
      <turningDirection>cw</turningDirection>
      <timeConstantUp>0.0125</timeConstantUp>
      <timeConstantDown>0.025</timeConstantDown>
      <maxRotVelocity>3500.0</maxRotVelocity>
      <motorConstant>8.54858e-06</motorConstant>
      <momentConstant>0.650</momentConstant>
      <commandSubTopic>command/motor_speed</commandSubTopic>
      <motorNumber>2</motorNumber>
      <rotorDragCoefficient>8.06428e-05</rotorDragCoefficient>
      <rollingMomentCoefficient>1e-06</rollingMomentCoefficient>
      <rotorVelocitySlowdownSim>10</rotorVelocitySlowdownSim>
      <motorType>velocity</motorType>
    </plugin>
    <plugin filename="gz-sim-multicopter-motor-model-system" name="gz::sim::systems::MulticopterMotorModel">
      <jointName>rotor_3_joint</jointName>
      <linkName>rotor_3</linkName>
      <turningDirection>ccw</turningDirection>
      <timeConstantUp>0.0125</timeConstantUp>
      <timeConstantDown>0.025</timeConstantDown>
      <maxRotVelocity>3500.0</maxRotVelocity>
      <motorConstant>8.54858e-06</motorConstant>
      <momentConstant>0.650</momentConstant>
      <commandSubTopic>command/motor_speed</commandSubTopic>
      <motorNumber>3</motorNumber>
      <rotorDragCoefficient>8.06428e-05</rotorDragCoefficient>
      <rollingMomentCoefficient>1e-06</rollingMomentCoefficient>
      <rotorVelocitySlowdownSim>10</rotorVelocitySlowdownSim>
      <motorType>velocity</motorType>
    </plugin>
    <plugin filename="gz-sim-multicopter-motor-model-system" name="gz::sim::systems::MulticopterMotorModel">
      <jointName>rotor_4_joint</jointName>
      <linkName>rotor_4</linkName>
      <turningDirection>cw</turningDirection>
      <timeConstantUp>0.0125</timeConstantUp>
      <timeConstantDown>0.025</timeConstantDown>
      <maxRotVelocity>3500.0</maxRotVelocity>
      <motorConstant>8.54858e-06</motorConstant>
      <momentConstant>0.650</momentConstant>
      <commandSubTopic>command/motor_speed</commandSubTopic>
      <motorNumber>4</motorNumber>
      <rotorDragCoefficient>8.06428e-05</rotorDragCoefficient>
      <rollingMomentCoefficient>1e-06</rollingMomentCoefficient>
      <rotorVelocitySlowdownSim>10</rotorVelocitySlowdownSim>
      <motorType>velocity</motorType>
    </plugin>
    <plugin filename="gz-sim-multicopter-motor-model-system" name="gz::sim::systems::MulticopterMotorModel">
      <jointName>rotor_5_joint</jointName>
      <linkName>rotor_5</linkName>
      <turningDirection>ccw</turningDirection>
      <timeConstantUp>0.0125</timeConstantUp>
      <timeConstantDown>0.025</timeConstantDown>
      <maxRotVelocity>3500.0</maxRotVelocity>
      <motorConstant>8.54858e-06</motorConstant>
      <momentConstant>0.650</momentConstant>
      <commandSubTopic>command/motor_speed</commandSubTopic>
      <motorNumber>5</motorNumber>
      <rotorDragCoefficient>8.06428e-05</rotorDragCoefficient>
      <rollingMomentCoefficient>1e-06</rollingMomentCoefficient>
      <rotorVelocitySlowdownSim>10</rotorVelocitySlowdownSim>
      <motorType>velocity</motorType>
    </plugin>
    <plugin filename="libSurfacePlace.so" name="vrx::SurfacePlace">
      <link_name>base_link</link_name>
      <hull_height>0.25</hull_height>
      <hull_radius>0.37</hull_radius>
      <fluid_level>0.0</fluid_level>
      <fluid_density>997</fluid_density>
      <points>
        <point>0 0 0</point>
        <point>0.12 0 0</point>
        <point>0.24 0 0</point>
        <point>-0.12 0 0</point>
        <point>-0.24 0 0</point>
        <point>0 0.12 0</point>
        <point>0 0.24 0</point>
        <point>0 -0.12 0</point>
        <point>0 -0.24 0</point>
        <point>0.12 0.12 0</point>
        <point>0.24 0.24 0</point>
        <point>-0.12 -0.12 0</point>
        <point>-0.24 -0.24 0</point>
        <point>0.12 -0.12 0</point>
        <point>0.24 -0.24 0</point>
        <point>-0.12 0.12 0</point>
        <point>-0.24 0.24 0</point>
      </points>
      <wavefield>
        <size>6000 6000</size>
     		<cell_count>500 500</cell_count>
        <topic>/vrx/wavefield/parameters</topic>
        <!--<wave>
       		<model>CWR</model>
       		<period>8</period>
       		<number>1</number>
       		<scale>2</scale>
       		<gain>6.0</gain>
      		<direction>0.0</direction>
       		<angle>0.4</angle>
       		<tau>0.6</tau>
       		<amplitude>3.0</amplitude>
       		<steepness>0.5</steepness>
     		</wave>-->
      </wavefield>
    </plugin>
    <plugin filename="libSurfacePlace.so" name="vrx::SurfacePlace">
      <link_name>base_link</link_name>
      <hull_height>0.283</hull_height>
      <hull_radius>0.05</hull_radius>
      <fluid_level>0.0</fluid_level>
      <fluid_density>997</fluid_density>
      <points>
        <point>0 0.8 0</point>
      </points>
      <wavefield>
        <size>6000 6000</size>
     		<cell_count>500 500</cell_count>
        <topic>/vrx/wavefield/parameters</topic>
        <!--<wave>
       		<model>CWR</model>
       		<period>8</period>
       		<number>1</number>
       		<scale>2</scale>
       		<gain>6.0</gain>
      		<direction>0.0</direction>
       		<angle>0.4</angle>
       		<tau>0.6</tau>
       		<amplitude>3.0</amplitude>
       		<steepness>0.5</steepness>
     		</wave>-->
      </wavefield>
    </plugin>
    <plugin filename="libSurfacePlace.so" name="vrx::SurfacePlace">
      <link_name>base_link</link_name>
      <hull_height>0.283</hull_height>
      <hull_radius>0.05</hull_radius>
      <fluid_level>0.0</fluid_level>
      <fluid_density>997</fluid_density>
      <points>
        <point>0.692 0.4 0</point>
      </points>
      <wavefield>
        <size>6000 6000</size>
     		<cell_count>500 500</cell_count>
        <topic>/vrx/wavefield/parameters</topic>
        <!--<wave>
       		<model>CWR</model>
       		<period>8</period>
       		<number>1</number>
       		<scale>2</scale>
       		<gain>6.0</gain>
      		<direction>0.0</direction>
       		<angle>0.4</angle>
       		<tau>0.6</tau>
       		<amplitude>3.0</amplitude>
       		<steepness>0.5</steepness>
     		</wave>-->
      </wavefield>
    </plugin>
    <plugin filename="libSurfacePlace.so" name="vrx::SurfacePlace">
      <link_name>base_link</link_name>
      <hull_height>0.283</hull_height>
      <hull_radius>0.05</hull_radius>
      <fluid_level>0.0</fluid_level>
      <fluid_density>997</fluid_density>
      <points>
        <point>0.692 -0.4 0</point>
      </points>
      <wavefield>
        <size>6000 6000</size>
     		<cell_count>500 500</cell_count>
        <topic>/vrx/wavefield/parameters</topic>
        <!--<wave>
       		<model>CWR</model>
       		<period>8</period>
       		<number>1</number>
       		<scale>2</scale>
       		<gain>6.0</gain>
      		<direction>0.0</direction>
       		<angle>0.4</angle>
       		<tau>0.6</tau>
       		<amplitude>3.0</amplitude>
       		<steepness>0.5</steepness>
     		</wave>-->
      </wavefield>
    </plugin>
    <plugin filename="libSurfacePlace.so" name="vrx::SurfacePlace">
      <link_name>base_link</link_name>
      <hull_height>0.283</hull_height>
      <hull_radius>0.05</hull_radius>
      <fluid_level>0.0</fluid_level>
      <fluid_density>997</fluid_density>
      <points>
        <point>0 -0.8 0</point>
      </points>
      <wavefield>
        <size>6000 6000</size>
     		<cell_count>500 500</cell_count>
        <topic>/vrx/wavefield/parameters</topic>
        <!--<wave>
       		<model>CWR</model>
       		<period>8</period>
       		<number>1</number>
       		<scale>2</scale>
       		<gain>6.0</gain>
      		<direction>0.0</direction>
       		<angle>0.4</angle>
       		<tau>0.6</tau>
       		<amplitude>3.0</amplitude>
       		<steepness>0.5</steepness>
     		</wave>-->
      </wavefield>
    </plugin>
    <plugin filename="libSurfacePlace.so" name="vrx::SurfacePlace">
      <link_name>base_link</link_name>
      <hull_height>0.283</hull_height>
      <hull_radius>0.05</hull_radius>
      <fluid_level>0.0</fluid_level>
      <fluid_density>997</fluid_density>
      <points>
        <point>-0.692 -0.4 0</point>
      </points>
      <wavefield>
        <size>6000 6000</size>
     		<cell_count>500 500</cell_count>
        <topic>/vrx/wavefield/parameters</topic>
        <!--<wave>
       		<model>CWR</model>
       		<period>8</period>
       		<number>1</number>
       		<scale>2</scale>
       		<gain>6.0</gain>
      		<direction>0.0</direction>
       		<angle>0.4</angle>
       		<tau>0.6</tau>
       		<amplitude>3.0</amplitude>
       		<steepness>0.5</steepness>
     		</wave>-->
      </wavefield>
    </plugin>
    <plugin filename="libSurfacePlace.so" name="vrx::SurfacePlace">
      <link_name>base_link</link_name>
      <hull_height>0.283</hull_height>
      <hull_radius>0.05</hull_radius>
      <fluid_level>0.0</fluid_level>
      <fluid_density>997</fluid_density>
      <points>
        <point>-0.692 0.4 0</point>
      </points>
      <wavefield>
        <size>6000 6000</size>
     		<cell_count>500 500</cell_count>
        <topic>/vrx/wavefield/parameters</topic>
        <!--<wave>
       		<model>CWR</model>
       		<period>8</period>
       		<number>1</number>
       		<scale>2</scale>
       		<gain>6.0</gain>
      		<direction>0.0</direction>
       		<angle>0.4</angle>
       		<tau>0.6</tau>
       		<amplitude>3.0</amplitude>
       		<steepness>0.5</steepness>
     		</wave>-->
      </wavefield>
    </plugin>
  </model>
</sdf>
