<?xml version="1.0" encoding="utf-8"?>
<sdf version='1.9'>
  <model name='holybro_x500'>
    <static>false</static>
    <pose>0 0 0.182 0 0 0</pose>

    <!-- BODY {-->
    <link name='base_link'>
      <gravity>true</gravity>
      <velocity_decay/>

      <inertial>
        <pose>0 0 0 0 0 0</pose>
        <mass>2.3</mass>
        <inertia>
          <ixx>0.052689166666666655</ixx>
          <ixy>0</ixy>
          <ixz>0</ixz>
          <iyy>0.052689166666666655</iyy>
          <iyz>0</iyz>
          <izz>0.1035</izz>
        </inertia>
      </inertial>

      <collision name='base_link_inertia_collision'>
        <pose>0 0 0.05 0 0 0</pose>
        <geometry>
          <cylinder>
            <length>0.259</length>
            <radius>0.094</radius>
          </cylinder>
        </geometry>
        <surface>
          <contact>
            <ode>
              <min_depth>0.001</min_depth>
              <max_vel>0</max_vel>
            </ode>
          </contact>
        </surface>
      </collision>

      <visual name='base_link_inertia_visual'>
        <pose>0 0 0 0 0 0</pose>
        <geometry>
          <mesh>
            <scale>1 1 1</scale>
            <uri>meshes/x500_central_body.dae</uri>
          </mesh>
        </geometry>
      </visual>

      <sensor name="imu_sensor" type="imu">
        <always_on>true</always_on>
        <update_rate>250</update_rate>
      </sensor>

      <sensor name="navsat_sensor" type="gps"/>
    </link>
    <!--} END BODY -->

    <!-- ARMS {-->

    <!-- ARM 0 {-->
    <link name="arm_0_link">
      <pose>0 0 0 0 0 1.5708</pose>
      <inertial>
        <mass>0.02</mass>
        <inertia>
          <ixx>0.000166667</ixx>
          <ixy>0</ixy>
          <ixz>0</ixz>
          <iyy>0.000166667</iyy>
          <iyz>0</iyz>
          <izz>0.000166667</izz>
        </inertia>
      </inertial>
      <visual name='arm_0_visual'>
        <pose>0 0 0 0 0 0</pose>
        <geometry>
          <mesh>
            <scale>1 1 1</scale>
            <uri>meshes/x500_arm.dae</uri>
          </mesh>
        </geometry>
      </visual>
      <visual name='arm_0_motor'>
        <pose>-0.175 -0.175 0.02 0 0 0</pose>
        <geometry>
          <mesh>
            <scale>1 1 1</scale>
            <uri>meshes/x500_motor.dae</uri>
          </mesh>
        </geometry>
      </visual>
      <collision name='arm_0_collision'>
        <pose>-0.155 -0.155 -0.104 0 0 0</pose>
        <geometry>
          <cylinder>
            <length>0.16</length>
            <radius>0.01</radius>
          </cylinder>
        </geometry>
        <surface>
          <contact>
            <ode>
              <min_depth>0.001</min_depth>
              <max_vel>0</max_vel>
            </ode>
          </contact>
        </surface>
      </collision>
    </link>
    <joint name='arm_0_joint' type='fixed'>
      <child>arm_0_link</child>
      <parent>base_link</parent>
    </joint>
    <!--} END ARM 0 -->

    <!-- ARM 1 {-->
    <link name="arm_1_link">
      <pose>0 0 0 0 0 -1.5708</pose>
      <inertial>
        <mass>0.02</mass>
        <inertia>
          <ixx>0.000166667</ixx>
          <ixy>0</ixy>
          <ixz>0</ixz>
          <iyy>0.000166667</iyy>
          <iyz>0</iyz>
          <izz>0.000166667</izz>
        </inertia>
      </inertial>
      <visual name='arm_1_visual'>
        <pose>0 0 0 0 0 0</pose>
        <geometry>
          <mesh>
            <scale>1 1 1</scale>
            <uri>meshes/x500_arm.dae</uri>
          </mesh>
        </geometry>
      </visual>
      <visual name='arm_1_motor'>
        <pose>-0.175 -0.175 0.02 0 0 0</pose>
        <geometry>
          <mesh>
            <scale>1 1 1</scale>
            <uri>meshes/x500_motor.dae</uri>
          </mesh>
        </geometry>
      </visual>
      <collision name='arm_1_collision'>
        <pose>-0.155 -0.155 -0.104 0 0 0</pose>
        <geometry>
          <cylinder>
            <length>0.16</length>
            <radius>0.01</radius>
          </cylinder>
        </geometry>
        <surface>
          <contact>
            <ode>
              <min_depth>0.001</min_depth>
              <max_vel>0</max_vel>
            </ode>
          </contact>
        </surface>
      </collision>
    </link>
    <joint name='arm_1_joint' type='fixed'>
      <child>arm_1_link</child>
      <parent>base_link</parent>
    </joint>
    <!--} END ARM 1 -->

    <!-- ARM 2 {-->
    <link name="arm_2_link">
      <pose>0 0 0 0 0 3.14159</pose>
      <inertial>
        <mass>0.02</mass>
        <inertia>
          <ixx>0.000166667</ixx>
          <ixy>0</ixy>
          <ixz>0</ixz>
          <iyy>0.000166667</iyy>
          <iyz>0</iyz>
          <izz>0.000166667</izz>
        </inertia>
      </inertial>
      <visual name='arm_2_visual'>
        <pose>0 0 0 0 0 0</pose>
        <geometry>
          <mesh>
            <scale>1 1 1</scale>
            <uri>meshes/x500_arm.dae</uri>
          </mesh>
        </geometry>
      </visual>
      <visual name='arm_2_motor'>
        <pose>-0.175 -0.175 0.02 0 0 0</pose>
        <geometry>
          <mesh>
            <scale>1 1 1</scale>
            <uri>meshes/x500_motor.dae</uri>
          </mesh>
        </geometry>
      </visual>
      <collision name='arm_2_collision'>
        <pose>-0.155 -0.155 -0.104 0 0 0</pose>
        <geometry>
          <cylinder>
            <length>0.16</length>
            <radius>0.01</radius>
          </cylinder>
        </geometry>
        <surface>
          <contact>
            <ode>
              <min_depth>0.001</min_depth>
              <max_vel>0</max_vel>
            </ode>
          </contact>
        </surface>
      </collision>
    </link>
    <joint name='arm_2_joint' type='fixed'>
      <child>arm_2_link</child>
      <parent>base_link</parent>
    </joint>
    <!--} END ARM 2 -->

    <!-- ARM 3 {-->
    <link name="arm_3_link">
      <pose>0 0 0 0 0 0</pose>
      <inertial>
        <mass>0.02</mass>
        <inertia>
          <ixx>0.000166667</ixx>
          <ixy>0</ixy>
          <ixz>0</ixz>
          <iyy>0.000166667</iyy>
          <iyz>0</iyz>
          <izz>0.000166667</izz>
        </inertia>
      </inertial>
      <visual name='arm_3_visual'>
        <pose>0 0 0 0 0 0</pose>
        <geometry>
          <mesh>
            <scale>1 1 1</scale>
            <uri>meshes/x500_arm.dae</uri>
          </mesh>
        </geometry>
      </visual>
      <visual name='arm_3_motor'>
        <pose>-0.175 -0.175 0.02 0 0 0</pose>
        <geometry>
          <mesh>
            <scale>1 1 1</scale>
            <uri>meshes/x500_motor.dae</uri>
          </mesh>
        </geometry>
      </visual>
      <collision name='arm_3_collision'>
        <pose>-0.155 -0.155 -0.104 0 0 0</pose>
        <geometry>
          <cylinder>
            <length>0.16</length>
            <radius>0.01</radius>
          </cylinder>
        </geometry>
        <surface>
          <contact>
            <ode>
              <min_depth>0.001</min_depth>
              <max_vel>0</max_vel>
            </ode>
          </contact>
        </surface>
      </collision>
    </link>
    <joint name='arm_3_joint' type='fixed'>
      <child>arm_3_link</child>
      <parent>base_link</parent>
    </joint>
    <!--} END ARM 3 -->
    <!--} END ARMS -->

    <!-- ROTORS {-->
    <link name='rotor_0'>
      <pose>0.175 -0.175 0.041 0 0 0</pose>
      <gravity>true</gravity>
      <self_collide>false</self_collide>
      <velocity_decay/>
      <inertial>
        <pose>0 0 0 0 0 0</pose>
        <mass>0.005</mass>
        <inertia>
          <ixx>0.0001</ixx>
          <ixy>0</ixy>
          <ixz>0</ixz>
          <iyy>0.0001</iyy>
          <iyz>0</iyz>
          <izz>0.0001</izz>
        </inertia>
      </inertial>
      <collision name='rotor_0_collision'>
        <pose>0 0 0 0 0 0</pose>
        <geometry>
          <cylinder>
            <length>0.009</length>
            <radius>0.128</radius>
          </cylinder>
        </geometry>
        <surface>
          <contact>
            <ode>
				 <min_depth>0.001</min_depth>
              <max_vel>0</max_vel>
			</ode>
          </contact>
          <friction>
            <ode/>
          </friction>
        </surface>
      </collision>
      <visual name='rotor_0_visual'>
        <pose>0 0 0 0 0 0</pose>
        <geometry>
          <mesh>
            <scale>1 1 1</scale>
            <uri>meshes/x500_propeller.dae</uri>
          </mesh>
        </geometry>
      </visual>
    </link>
    <joint name='rotor_0_joint' type='revolute'>
      <child>rotor_0</child>
      <parent>base_link</parent>
      <axis>
        <xyz>0 0 1</xyz>
        <limit>
          <lower>-1e+16</lower>
          <upper>1e+16</upper>
        </limit>
        <dynamics>
          <spring_reference>0</spring_reference>
          <spring_stiffness>0</spring_stiffness>
        </dynamics>
      </axis>
    </joint>
    <link name='rotor_1'>
      <gravity>true</gravity>
      <self_collide>false</self_collide>
      <velocity_decay/>
      <pose>-0.175 0.175 0.041 0 0 0</pose>
      <inertial>
        <pose>0 0 0 0 0 0</pose>
        <mass>0.005</mass>
        <inertia>
          <ixx>0.0001</ixx>
          <ixy>0</ixy>
          <ixz>0</ixz>
          <iyy>0.0001</iyy>
          <iyz>0</iyz>
          <izz>0.0001</izz>
        </inertia>
      </inertial>
      <collision name='rotor_1_collision'>
        <pose>0 0 0 0 0 0</pose>
        <geometry>
          <cylinder>
            <length>0.009</length>
            <radius>0.128</radius>
          </cylinder>
        </geometry>
        <surface>
          <contact>
            <ode>
				 <min_depth>0.001</min_depth>
              <max_vel>0</max_vel>
			</ode>
          </contact>
          <friction>
            <ode/>
          </friction>
        </surface>
      </collision>
      <visual name='rotor_1_visual'>
        <pose>0 0 0 0 0 0</pose>
        <geometry>
          <mesh>
            <scale>1 1 1</scale>
            <uri>meshes/x500_propeller.dae</uri>
          </mesh>
        </geometry>
      </visual>
    </link>
    <joint name='rotor_1_joint' type='revolute'>
      <child>rotor_1</child>
      <parent>base_link</parent>
      <axis>
        <xyz>0 0 1</xyz>
        <limit>
          <lower>-1e+16</lower>
          <upper>1e+16</upper>
        </limit>
        <dynamics>
          <spring_reference>0</spring_reference>
          <spring_stiffness>0</spring_stiffness>
        </dynamics>
      </axis>
    </joint>
    <link name='rotor_2'>
      <gravity>true</gravity>
      <self_collide>false</self_collide>
      <velocity_decay/>
      <pose>0.175 0.175 0.041 0 0 0</pose>
      <inertial>
        <pose>0 0 0 0 0 0</pose>
        <mass>0.005</mass>
        <inertia>
          <ixx>0.0001</ixx>
          <ixy>0</ixy>
          <ixz>0</ixz>
          <iyy>0.0001</iyy>
          <iyz>0</iyz>
          <izz>0.0001</izz>
        </inertia>
      </inertial>
      <collision name='rotor_2_collision'>
        <pose>0 0 0 0 0 0</pose>
        <geometry>
          <cylinder>
            <length>0.009</length>
            <radius>0.128</radius>
          </cylinder>
        </geometry>
        <surface>
          <contact>
            <ode>
				 <min_depth>0.001</min_depth>
              <max_vel>0</max_vel>
			</ode>
          </contact>
          <friction>
            <ode/>
          </friction>
        </surface>
      </collision>
      <visual name='rotor_2_visual'>
        <pose>0 0 0 0 0 0</pose>
        <geometry>
          <mesh>
            <scale>-1 1 1</scale>
            <uri>meshes/x500_propeller.dae</uri>
          </mesh>
        </geometry>
      </visual>
    </link>
    <joint name='rotor_2_joint' type='revolute'>
      <child>rotor_2</child>
      <parent>base_link</parent>
      <axis>
        <xyz>0 0 1</xyz>
        <limit>
          <lower>-1e+16</lower>
          <upper>1e+16</upper>
        </limit>
        <dynamics>
          <spring_reference>0</spring_reference>
          <spring_stiffness>0</spring_stiffness>
        </dynamics>
      </axis>
    </joint>
    <link name='rotor_3'>
      <gravity>true</gravity>
      <self_collide>false</self_collide>
      <velocity_decay/>
      <pose>-0.175 -0.175 0.041 0 0 0</pose>
      <inertial>
        <pose>0 0 0 0 0 0</pose>
        <mass>0.005</mass>
        <inertia>
          <ixx>0.0001</ixx>
          <ixy>0</ixy>
          <ixz>0</ixz>
          <iyy>0.0001</iyy>
          <iyz>0</iyz>
          <izz>0.0001</izz>
        </inertia>
      </inertial>
      <collision name='rotor_3_collision'>
        <pose>0 0 0 0 0 0</pose>
        <geometry>
          <cylinder>
            <length>0.009</length>
            <radius>0.128</radius>
          </cylinder>
        </geometry>
        <surface>
          <contact>
            <ode>
				 <min_depth>0.001</min_depth>
              <max_vel>0</max_vel>
			</ode>
          </contact>
          <friction>
            <ode/>
          </friction>
        </surface>
      </collision>
      <visual name='rotor_3_visual'>
        <pose>0 0 0 0 0 0</pose>
        <geometry>
          <mesh>
            <scale>-1 1 1</scale>
            <uri>meshes/x500_propeller.dae</uri>
          </mesh>
        </geometry>
      </visual>
    </link>
    <joint name='rotor_3_joint' type='revolute'>
      <child>rotor_3</child>
      <parent>base_link</parent>
      <axis>
        <xyz>0 0 1</xyz>
        <limit>
          <lower>-1e+16</lower>
          <upper>1e+16</upper>
        </limit>
        <dynamics>
          <spring_reference>0</spring_reference>
          <spring_stiffness>0</spring_stiffness>
        </dynamics>
      </axis>
    </joint>
    <!--} END ROTORS -->

    <!-- PLUGINS {-->
    <!-- MOTOR PLUGINS {-->
    <plugin filename="gz-sim-multicopter-motor-model-system" name="gz::sim::systems::MulticopterMotorModel">
      <jointName>rotor_0_joint</jointName>
      <linkName>rotor_0</linkName>
      <turningDirection>ccw</turningDirection>
      <timeConstantUp>0.0125</timeConstantUp>
      <timeConstantDown>0.025</timeConstantDown>
      <maxRotVelocity>1000.0</maxRotVelocity>
      <motorConstant>8.54858e-06</motorConstant>
      <momentConstant>0.016</momentConstant>
      <commandSubTopic>command/motor_speed</commandSubTopic>
      <motorNumber>0</motorNumber>
      <rotorDragCoefficient>8.06428e-05</rotorDragCoefficient>
      <rollingMomentCoefficient>1e-06</rollingMomentCoefficient>
      <rotorVelocitySlowdownSim>10</rotorVelocitySlowdownSim>
      <motorType>velocity</motorType>
    </plugin>
    <plugin filename="gz-sim-multicopter-motor-model-system" name="gz::sim::systems::MulticopterMotorModel">
      <jointName>rotor_1_joint</jointName>
      <linkName>rotor_1</linkName>
      <turningDirection>ccw</turningDirection>
      <timeConstantUp>0.0125</timeConstantUp>
      <timeConstantDown>0.025</timeConstantDown>
      <maxRotVelocity>1000.0</maxRotVelocity>
      <motorConstant>8.54858e-06</motorConstant>
      <momentConstant>0.016</momentConstant>
      <commandSubTopic>command/motor_speed</commandSubTopic>
      <motorNumber>1</motorNumber>
      <rotorDragCoefficient>8.06428e-05</rotorDragCoefficient>
      <rollingMomentCoefficient>1e-06</rollingMomentCoefficient>
      <rotorVelocitySlowdownSim>10</rotorVelocitySlowdownSim>
      <motorType>velocity</motorType>
    </plugin>
    <plugin filename="gz-sim-multicopter-motor-model-system" name="gz::sim::systems::MulticopterMotorModel">
      <jointName>rotor_2_joint</jointName>
      <linkName>rotor_2</linkName>
      <turningDirection>cw</turningDirection>
      <timeConstantUp>0.0125</timeConstantUp>
      <timeConstantDown>0.025</timeConstantDown>
      <maxRotVelocity>1000.0</maxRotVelocity>
      <motorConstant>8.54858e-06</motorConstant>
      <momentConstant>0.016</momentConstant>
      <commandSubTopic>command/motor_speed</commandSubTopic>
      <motorNumber>2</motorNumber>
      <rotorDragCoefficient>8.06428e-05</rotorDragCoefficient>
      <rollingMomentCoefficient>1e-06</rollingMomentCoefficient>
      <rotorVelocitySlowdownSim>10</rotorVelocitySlowdownSim>
      <motorType>velocity</motorType>
    </plugin>
    <plugin filename="gz-sim-multicopter-motor-model-system" name="gz::sim::systems::MulticopterMotorModel">
      <jointName>rotor_3_joint</jointName>
      <linkName>rotor_3</linkName>
      <turningDirection>cw</turningDirection>
      <timeConstantUp>0.0125</timeConstantUp>
      <timeConstantDown>0.025</timeConstantDown>
      <maxRotVelocity>1000.0</maxRotVelocity>
      <motorConstant>8.54858e-06</motorConstant>
      <momentConstant>0.016</momentConstant>
      <commandSubTopic>command/motor_speed</commandSubTopic>
      <motorNumber>3</motorNumber>
      <rotorDragCoefficient>8.06428e-05</rotorDragCoefficient>
      <rollingMomentCoefficient>1e-06</rollingMomentCoefficient>
      <rotorVelocitySlowdownSim>10</rotorVelocitySlowdownSim>
      <motorType>velocity</motorType>
    </plugin>
    <!--} END MOTOR PLUGINS -->

    <!-- THIRD PERSON CAMERA {-->
    <link name="camera_link">
      <kinematic>1</kinematic>
      <pose>-2 0 1 0 0.3 0</pose>
      <inertial>
        <mass>0</mass>
        <inertia>
          <ixx>0.0</ixx>
          <iyy>0.0</iyy>
          <izz>0.0</izz>
        </inertia>
      </inertial>
      <sensor type="camera" name="third-person-camera">
        <camera>
          <horizontal_fov>1.7</horizontal_fov>
          <image>
            <width>1280</width>
            <height>720</height>
          </image>
          <clip>
            <near>0.1</near>
            <far>1000</far>
          </clip>
        </camera>
        <always_on>true</always_on>
        <update_rate>30</update_rate>
        <visualize>true</visualize>
      </sensor>
    </link>
    <joint name='camera_joint' type='fixed'>
      <kinematic>1</kinematic>
      <child>camera_link</child>
      <parent>base_link</parent>
      <axis>
        <xyz>50 -50 50</xyz>
        <limit>
          <lower>0</lower>
          <upper>0</upper>
          <effort>0</effort>
          <velocity>0</velocity>
        </limit>
        <dynamics>
          <spring_reference>0</spring_reference>
          <spring_stiffness>0</spring_stiffness>
        </dynamics>
      </axis>
    </joint>
    <!--} END THIRD PERSON CAMERA -->

    <!-- GIMBAL CAMERA {-->
    <link name="gimbal_camera_link">
      <pose>0 0 0 0 1.57 0</pose>
      <inertial>
        <mass>0.01</mass>
        <inertia>
          <ixx>0.000166667</ixx>
          <iyy>0.000166667</iyy>
          <izz>0.000166667</izz>
        </inertia>
      </inertial>
      <collision name="collision">
        <geometry>
          <box>
            <size>0.01 0.01 0.01</size>
          </box>
        </geometry>
      </collision>
      <visual name="visual">
        <geometry>
          <box>
            <size>0.01 0.01 0.01</size>
          </box>
        </geometry>
      </visual>
      <sensor type="camera" name="onboard-gimbal-camera">
        <camera>
          <horizontal_fov>1.047</horizontal_fov>
          <image>
            <width>1280</width>
            <height>720</height>
          </image>
          <clip>
            <near>0.1</near>
            <far>100</far>
          </clip>
        </camera>
        <always_on>true</always_on>
        <update_rate>30</update_rate>
        <visualize>true</visualize>
      </sensor>
    </link>
    <joint name='camera_joint_tilt' type='revolute'>
      <child>gimbal_camera_link</child>
      <parent>camera_link_pan</parent>
      <axis>
        <xyz>0 1 0</xyz>
      </axis>
    </joint>
    <link name="camera_link_pan">
      <inertial>
        <mass>0.01</mass>
        <inertia>
          <ixx>0.000166667</ixx>
          <iyy>0.000166667</iyy>
          <izz>0.000166667</izz>
        </inertia>
      </inertial>
      <visual name="visual">
        <geometry>
          <empty/>
        </geometry>
        <transparency>1</transparency>
      </visual>
      <collision name="collision">
        <geometry>
          <empty/>
        </geometry>
      </collision>
    </link>
    <joint name='camera_joint_pan' type='revolute'>
      <child>camera_link_pan</child>
      <parent>base_link</parent>
      <axis>
        <xyz>0 0 1</xyz>
      </axis>
    </joint>
    <!--} END GIMBAL CAMERA -->

    <!-- RP LIDAR {-->
    <link name="2d_scanner_link">
      <pose>0 0 0.089 0 0 0</pose>
      <inertial>
        <mass>0.01</mass>
        <inertia>
          <ixx>0.000166667</ixx>
          <iyy>0.000166667</iyy>
          <izz>0.000166667</izz>
        </inertia>
      </inertial>
      <sensor name="rplidar" type="gpu_lidar">
        <always_on>true</always_on>
        <update_rate>20</update_rate>
        <visualize>false</visualize>
        <ray>
          <scan>
            <horizontal>
              <samples>720</samples>
              <resolution>1</resolution>
              <min_angle>-3.1241390751</min_angle>
              <max_angle>3.1241390751</max_angle>
            </horizontal>
          </scan>
          <range>
            <min>0.15</min>
            <max>14</max>
            <resolution>0.01</resolution>
          </range>
          <noise>
            <type>gaussian</type>
            <mean>0.0</mean>
            <stddev>0.01</stddev>
          </noise>
        </ray>
      </sensor>
      <visual name='rplidar_visual'>
        <pose>0 0 0 0 0 0</pose>
        <geometry>
          <mesh>
            <scale>1 1 1</scale>
            <uri>meshes/x500_rplidar.dae</uri>
          </mesh>
        </geometry>
      </visual>
    </link>
    <joint name='2d_scanner_joint' type='fixed'>
      <child>2d_scanner_link</child>
      <parent>base_link</parent>
    </joint>
    <!--} END RP LIDAR -->

    <!-- GARMIN RANGEFINDER {-->
    <link name="lidar0_link">
      <pose>-0.007 -0.04 -0.039 0 1.5708 1.5708</pose>
      <inertial>
        <mass>0.01</mass>
        <inertia>
          <ixx>0.000166667</ixx>
          <iyy>0.000166667</iyy>
          <izz>0.000166667</izz>
        </inertia>
      </inertial>
      <visual name='garmin_visual'>
        <pose>0 0 0 0 0 0</pose>
        <geometry>
          <mesh>
            <scale>0.001 0.001 0.001</scale>
            <uri>meshes/garmin_lidar_v3.stl</uri>
          </mesh>
        </geometry>
          <material>
            <script>
              <name>Gazebo/Black</name>
              <uri>file://media/materials/scripts/gazebo.material</uri>
            </script>
          </material>
        <material>
          <script>
            <name>Gazebo/DarkGrey</name>
            <uri>file://media/materials/scripts/gazebo.material</uri>
          </script>
        </material>
      </visual>
      <sensor name="garmin" type="gpu_lidar">
        <always_on>true</always_on>
        <update_rate>100</update_rate>
        <visualize>false</visualize>
        <ray>
          <scan>
            <horizontal>
              <samples>1</samples>
              <resolution>1</resolution>
              <min_angle>-0</min_angle>
              <max_angle>0</max_angle>
            </horizontal>
          </scan>
          <range>
            <min>0.06</min> <!-- do not change: use min_distance (below) for realistic behavior (smaller values cause issues) -->
            <max>35</max>   <!-- do not change: use max_distance (below) for realistic behavior (bigger values cause issues) -->
            <resolution>0.01</resolution>
          </range>
          <noise>
            <type>gaussian</type>
            <mean>0.0</mean>
            <stddev>0.01</stddev>
          </noise>
        </ray>
        <!-- <plugin name="drone-placeholder-1_garmin" filename="libgazebo_lidar_plugin.so"> -->
        <!--   <robotNamespace></robotNamespace> -->
        <!--   <min_distance>0.1</min_distance> -->
        <!--   <max_distance>30.0</max_distance> -->
        <!-- </plugin> -->
      </sensor>
    </link>
    <!-- name of the link for garmin has to contain lidar word to be detected by mavlink gazebo plugin -->
    <joint name='lidar0_joint' type='fixed'>
      <child>lidar0_link</child>
      <parent>base_link</parent>
    </joint>
    <!--} END GARMIN RANGEFINDER -->

    <plugin
        filename="gz-sim-pose-publisher-system"
        name="gz::sim::systems::PosePublisher">
      <publish_link_pose>true</publish_link_pose>
      <publish_nested_model_pose>true</publish_nested_model_pose>
      <use_pose_vector_msg>true</use_pose_vector_msg>
      <static_publisher>true</static_publisher>
      <static_update_frequency>1</static_update_frequency>
    </plugin>

    <plugin
        filename="gz-sim-odometry-publisher-system"
        name="gz::sim::systems::OdometryPublisher">
      <dimensions>3</dimensions>
    </plugin>

    <plugin
        filename="gz-sim-joint-position-controller-system"
        name="gz::sim::systems::JointPositionController">
      <joint_name>camera_joint_pan</joint_name>
      <p_gain>1</p_gain>
      <i_gain>0.1</i_gain>
      <d_gain>0.01</d_gain>
      <i_max>1</i_max>
      <i_min>-1</i_min>
      <cmd_max>1000</cmd_max>
      <cmd_min>-1000</cmd_min>
    </plugin>

    <plugin
        filename="gz-sim-joint-position-controller-system"
        name="gz::sim::systems::JointPositionController">
      <joint_name>camera_joint_tilt</joint_name>
      <p_gain>1</p_gain>
      <i_gain>0.1</i_gain>
      <d_gain>0.01</d_gain>
      <i_max>1</i_max>
      <i_min>-1</i_min>
      <cmd_max>1000</cmd_max>
      <cmd_min>-1000</cmd_min>
    </plugin>

    <plugin
        filename="gz-sim-joint-state-publisher-system"
        name="gz::sim::systems::JointStatePublisher">
      <joint_name>camera_joint_pan</joint_name>
    </plugin>

    <plugin
        filename="gz-sim-joint-state-publisher-system"
        name="gz::sim::systems::JointStatePublisher">
      <joint_name>camera_joint_tilt</joint_name>
    </plugin>

    {% if hitl_mode %}<plugin
          filename="libmavlink_hitl_gazebosim.so"
          name="mavlink_interface::GazeboMavlinkInterface">
      <robotNamespace/>
      <imuSubTopic>/link/base_link/sensor/imu_sensor/imu</imuSubTopic>
      <gpsSubTopic>/link/base_link/sensor/navsat_sensor/navsat</gpsSubTopic>
      <poseSubTopic>/pose/info</poseSubTopic>
      <mavlink_addr>{{ mavlink_addr }}</mavlink_addr>
      <mavlink_udp_local_port>{{ mavlink_udp_local_port }}</mavlink_udp_local_port>
      <mavlink_udp_remote_port>{{ mavlink_udp_remote_port }}</mavlink_udp_remote_port>
      <mavlink_tcp_port>{{ mavlink_tcp_port }}</mavlink_tcp_port>
      <use_tcp>0</use_tcp>
    </plugin>{% endif %}
    <!--} END PLUGINS -->
  </model>
</sdf>
