<?xml version="1.0"?>
<!--
  http://skywalkermodel.com/en/76.html
-->
<sdf version='1.5'>
  <model name='skywalker_x8'>
    <static>false</static>
    <pose>0 0 0.246 0 0 0</pose>

    <link name='base_link'>
      <pose>0 0 0 0 0 0</pose>
      <inertial>
        <pose>0 0 0 0 0 0</pose>
        <mass>0.75</mass>
        <inertia>
          <ixx>0.197563</ixx>
          <ixy>0</ixy>
          <ixz>0</ixz>
          <iyy>0.1458929</iyy>
          <iyz>0</iyz>
          <izz>0.1477</izz>
        </inertia>
      </inertial>
      <collision name='base_link_collision'>
        <pose>0.2 0 -0.07 0 0 0</pose>
        <geometry>
          <box>
            <size>0.55 0.4 0.05</size>
          </box>
        </geometry>
        <surface>
          <contact>
            <ode>
              <max_vel>50</max_vel>
              <min_depth>0.001</min_depth>
            </ode>
          </contact>
        </surface>
      </collision>
      <visual name='base_link_visual'>
        <pose>0.53 -1.072 -0.1 1.5707963268 0 3.1415926536</pose>
        <geometry>
          <mesh>
            <scale>0.001 0.001 0.001</scale>
            <uri>meshes/x8_wing.dae</uri>
          </mesh>
        </geometry>
        <material>
          <ambient>.175 .175 .175 1.0</ambient>
          <diffuse>.175 .175 .175 1.0</diffuse>
        </material>
      </visual>
      <gravity>1</gravity>
      <velocity_decay/>
      <self_collide>0</self_collide>
      <sensor name="imu_sensor" type="imu">
        <always_on>1</always_on>
        <update_rate>250</update_rate>
      </sensor>
      <sensor name="navsat_sensor" type="gps"/>
    </link>

    <link name="camera_link">
      <kinematic>1</kinematic>
      <pose>-2 0 1 0 0.3 0</pose>
      <inertial>
        <mass>0</mass>
        <inertia>
          <ixx>0.0</ixx>
          <iyy>0.0</iyy>
          <izz>0.0</izz>
        </inertia>
      </inertial>
      <!-- <visual name="visual">
        <geometry>
          <box>
            <size>0.1 0.1 0.1</size>
          </box>
        </geometry>
      </visual> -->
      <sensor type="camera" name="third-person-camera">
        <camera>
          <horizontal_fov>1.7</horizontal_fov>
          <image>
            <width>1280</width>
            <height>720</height>
          </image>
          <clip>
            <near>0.1</near>
            <far>1000</far>
          </clip>
        </camera>
        <always_on>true</always_on>
        <update_rate>30</update_rate>
        <visualize>true</visualize>
      </sensor>
    </link>
    <joint name='camera_joint' type='fixed'>
      <kinematic>1</kinematic>
      <child>camera_link</child>
      <parent>base_link</parent>
      <axis>
        <xyz>100 -100 100</xyz>
        <limit>
          <lower>0</lower>
          <upper>0</upper>
          <effort>0</effort>
          <velocity>0</velocity>
        </limit>
        <dynamics>
          <spring_reference>0</spring_reference>
          <spring_stiffness>0</spring_stiffness>
        </dynamics>
      </axis>
    </joint>

    <link name='rotor_pusher'>
      <pose>-0.22 0 0.0 0 1.57 0</pose>
      <inertial>
        <pose>0 0 0 0 0 0</pose>
        <mass>0.005</mass>
        <inertia>
          <ixx>9.75e-07</ixx>
          <ixy>0</ixy>
          <ixz>0</ixz>
          <iyy>0.000166704</iyy>
          <iyz>0</iyz>
          <izz>0.000167604</izz>
        </inertia>
      </inertial>
      <collision name='rotor_pusher_collision'>
        <pose>0.0 0 -0.04 0 0 0</pose>
        <geometry>
          <cylinder>
            <length>0.005</length>
            <radius>0.06</radius>
          </cylinder>
        </geometry>
        <surface>
          <contact>
            <ode/>
          </contact>
          <friction>
            <ode/>
          </friction>
        </surface>
      </collision>
      <visual name='rotor_pusher_visual'>
        <pose>0 0 -0.04 0 0 0</pose>
        <geometry>
          <mesh>
            <scale>0.8 0.8 0.8</scale>
            <uri>meshes/x8_prop_ccw.dae</uri>
          </mesh>
        </geometry>
        <material>
          <ambient>.175 .175 1.0 1.0</ambient>
          <diffuse>.175 .175 1.0 1.0</diffuse>
        </material>
      </visual>
      <gravity>1</gravity>
      <velocity_decay/>
      <self_collide>0</self_collide>
    </link>
    <joint name='rotor_pusher_joint' type='revolute'>
      <child>rotor_pusher</child>
      <parent>base_link</parent>
      <axis>
        <xyz>1 0 0</xyz>
        <limit>
          <lower>-1e+16</lower>
          <upper>1e+16</upper>
        </limit>
        <dynamics>
          <spring_reference>0</spring_reference>
          <spring_stiffness>0</spring_stiffness>
        </dynamics>
        <use_parent_model_frame>1</use_parent_model_frame>
      </axis>
    </joint>

    <!-- left elevon {-->
    <link name="left_elevon">
      <inertial>
        <mass>0.00000001</mass>
        <inertia>
          <ixx>0.000001</ixx>
          <ixy>0.0</ixy>
          <iyy>0.000001</iyy>
          <ixz>0.0</ixz>
          <iyz>0.0</iyz>
          <izz>0.000001</izz>
        </inertia>
        <pose>0 0.3 0 0.00 0 0.0</pose>
      </inertial>
      <visual name='left_elevon_visual'>
        <pose>-0.105 0.004 -0.034 1.5707963268 0 3.1415926536</pose>
        <geometry>
          <mesh>
            <scale>0.001 0.001 0.001</scale>
            <uri>meshes/x8_elevon_left.dae</uri>
          </mesh>
        </geometry>
        <material>
          <ambient>.175 .175 1.0 1.0</ambient>
          <diffuse>.175 .175 1.0 1.0</diffuse>
        </material>
      </visual>
    </link>

    <joint name='servo_0' type='revolute'>
      <parent>base_link</parent>
      <child>left_elevon</child>
      <pose>-0.18 0.6 -0.005 0 0 0.265</pose>
      <axis>
        <xyz>0 1 0</xyz>
        <limit>
          <!-- -30/+30 deg. -->
          <lower>-0.53</lower>
          <upper>0.53</upper>
        </limit>
        <dynamics>
          <damping>1.000</damping>
        </dynamics>
      </axis>
      <physics>
        <ode>
          <implicit_spring_damper>1</implicit_spring_damper>
        </ode>
      </physics>
    </joint>
    <!--}-->

    <!-- right elevon {-->
    <link name="right_elevon">
      <inertial>
        <mass>0.00000001</mass>
        <inertia>
          <ixx>0.000001</ixx>
          <ixy>0.0</ixy>
          <iyy>0.000001</iyy>
          <ixz>0.0</ixz>
          <iyz>0.0</iyz>
          <izz>0.000001</izz>
        </inertia>
        <pose>0 -0.6 0 0.00 0 0.0</pose>
      </inertial>
      <visual name='right_elevon_visual'>
        <pose>0.281 -1.032 -0.034 1.5707963268 0 3.1415926536</pose>
        <geometry>
          <mesh>
            <scale>0.001 0.001 0.001</scale>
            <uri>meshes/x8_elevon_right.dae</uri>
          </mesh>
        </geometry>
        <material>
          <ambient>.175 .175 1.0 1.0</ambient>
          <diffuse>.175 .175 1.0 1.0</diffuse>
        </material>
      </visual>
    </link>

    <joint name='servo_1' type='revolute'>
      <parent>base_link</parent>
      <child>right_elevon</child>
      <pose>-0.18 -0.6 -0.005 0 0 -0.265</pose>
      <axis>
        <xyz>0 1 0</xyz>
        <limit>
          <!-- -30/+30 deg. -->
          <lower>-0.53</lower>
          <upper>0.53</upper>
        </limit>
        <dynamics>
          <damping>1.000</damping>
        </dynamics>
      </axis>
      <physics>
        <ode>
          <implicit_spring_damper>1</implicit_spring_damper>
        </ode>
      </physics>
    </joint>
    <!--}-->

    <!-- lift plugins {-->

    <!-- body lift {-->
    <plugin filename="gz-sim-lift-drag-system" name="gz::sim::systems::LiftDrag">
      <a0>0.05984281113</a0>
      <cla>4.752798721</cla>
      <cda>0.6417112299</cda>
      <cma>0.0</cma>
      <alpha_stall>0.3391428111</alpha_stall>
      <cla_stall>-3.85</cla_stall>
      <cda_stall>-0.9233984055</cda_stall>
      <cma_stall>0</cma_stall>
      <cp>-0.05 0.0 0.05</cp>
      <area>0.7</area>
      <air_density>1.2041</air_density>
      <forward>1 0 0</forward>
      <upward>0 0 1</upward>
      <link_name>base_link</link_name>
    </plugin>
    <!--}-->

    <!-- left tailwing {-->
    <plugin filename="gz-sim-lift-drag-system" name="gz::sim::systems::LiftDrag">
      <a0>0.0</a0>
      <cla>4.752798721</cla>
      <cda>0.6417112299</cda>
      <cma>0.0</cma>
      <alpha_stall>0.3391428111</alpha_stall>
      <cla_stall>-3.85</cla_stall>
      <cda_stall>-0.9233984055</cda_stall>
      <cma_stall>0</cma_stall>
      <cp>-0.3 1.06 0.08</cp>
      <area>0.02</area>
      <air_density>1.2041</air_density>
      <forward>1 0 0</forward>
      <upward>0 1 0</upward>
      <link_name>base_link</link_name>
    </plugin>
    <!--}-->

    <!-- right tailwing {-->
    <plugin filename="gz-sim-lift-drag-system" name="gz::sim::systems::LiftDrag">
      <a0>0.0</a0>
      <cla>4.752798721</cla>
      <cda>0.6417112299</cda>
      <cma>0.0</cma>
      <alpha_stall>0.3391428111</alpha_stall>
      <cla_stall>-3.85</cla_stall>
      <cda_stall>-0.9233984055</cda_stall>
      <cma_stall>0</cma_stall>
      <cp>-0.3 -1.06 0.08</cp>
      <area>0.02</area>
      <air_density>1.2041</air_density>
      <forward>1 0 0</forward>
      <upward>0 1 0</upward>
      <link_name>base_link</link_name>
    </plugin>
    <!--}-->

    <!-- left elevon {-->
    <plugin filename="gz-sim-lift-drag-system" name="gz::sim::systems::LiftDrag">
      <a0>0.05984281113</a0>
      <cla>4.752798721</cla>
      <cda>0.6417112299</cda>
      <cma>0.0</cma>
      <alpha_stall>0.3391428111</alpha_stall>
      <cla_stall>-3.85</cla_stall>
      <cda_stall>-0.9233984055</cda_stall>
      <cma_stall>0</cma_stall>
      <cp>-0.13 0.45 0</cp>
      <area>0.15</area>
      <air_density>1.2041</air_density>
      <forward>0.96766 0.25225 0</forward>
      <upward>0 0 1</upward>
      <link_name>base_link</link_name>
      <control_joint_name>
        servo_0
      </control_joint_name>
      <control_joint_rad_to_cl>-2.5</control_joint_rad_to_cl>
    </plugin>
    <plugin
      filename="gz-sim-joint-position-controller-system" name="gz::sim::systems::JointPositionController">
      <joint_name>servo_0</joint_name>
      <sub_topic>servo_0</sub_topic>
      <p_gain>10.0</p_gain>
    </plugin>
    <!--}-->

    <!-- right elevon {-->
    <plugin filename="gz-sim-lift-drag-system" name="gz::sim::systems::LiftDrag">
      <a0>0.05984281113</a0>
      <cla>4.752798721</cla>
      <cda>0.6417112299</cda>
      <cma>0.0</cma>
      <alpha_stall>0.3391428111</alpha_stall>
      <cla_stall>-3.85</cla_stall>
      <cda_stall>-0.9233984055</cda_stall>
      <cma_stall>0</cma_stall>
      <cp>-0.13 -0.45 0</cp>
      <area>0.15</area>
      <air_density>1.2041</air_density>
      <forward>0.96766 -0.25225 0 0</forward>
      <upward>0 0 1</upward>
      <link_name>base_link</link_name>
      <control_joint_name>
        servo_1
      </control_joint_name>
      <control_joint_rad_to_cl>-2.5</control_joint_rad_to_cl>
    </plugin>
    <plugin
      filename="gz-sim-joint-position-controller-system" name="gz::sim::systems::JointPositionController">
      <joint_name>servo_1</joint_name>
      <sub_topic>servo_1</sub_topic>
      <p_gain>10.0</p_gain>
    </plugin>
    <!--}-->

    <!--}-->

    <!-- pusher motor {-->
    <plugin filename="gz-sim-multicopter-motor-model-system" name="gz::sim::systems::MulticopterMotorModel">
      <jointName>rotor_pusher_joint</jointName>
      <linkName>rotor_pusher</linkName>
      <turningDirection>cw</turningDirection>
      <timeConstantUp>0.0125</timeConstantUp>
      <timeConstantDown>0.025</timeConstantDown>
      <maxRotVelocity>3500</maxRotVelocity>
      <motorConstant>8.54858e-06</motorConstant>
      <momentConstant>0.01</momentConstant>
      <commandSubTopic>command/motor_speed</commandSubTopic>
      <motorNumber>0</motorNumber>
      <rotorDragCoefficient>0.000106428</rotorDragCoefficient>
      <rollingMomentCoefficient>1e-06</rollingMomentCoefficient>
      <rotorVelocitySlowdownSim>20</rotorVelocitySlowdownSim>
      <motorType>velocity</motorType>
    </plugin>
    <!--}-->

    {% if hitl_mode %}<plugin
          filename="libmavlink_hitl_gazebosim.so"
          name="mavlink_interface::GazeboMavlinkInterface">
      <robotNamespace/>
      <imuSubTopic>/link/base_link/sensor/imu_sensor/imu</imuSubTopic>
      <gpsSubTopic>/link/base_link/sensor/navsat_sensor/navsat</gpsSubTopic>
      <poseSubTopic>/pose/info</poseSubTopic>
      <mavlink_addr>{{ mavlink_addr }}</mavlink_addr>
      <mavlink_udp_local_port>{{ mavlink_udp_local_port }}</mavlink_udp_local_port>
      <mavlink_udp_remote_port>{{ mavlink_udp_remote_port }}</mavlink_udp_remote_port>
      <mavlink_tcp_port>{{ mavlink_tcp_port }}</mavlink_tcp_port>
      <use_tcp>0</use_tcp>
    </plugin>{% endif %}
  </model>
</sdf>
